Workbook

Sheet Code Dumps to help
B2: Starting party | C2: public enum PartyLayoutType implements ChanceHaver { Basic(RarityUtils.IGNORED_RARITY, new HeroCol[]{HeroCol.orange, HeroCol.yellow, HeroCol.grey, HeroCol.red, HeroCol.blue}), Greens(1.0F, new HeroCol[]{HeroCol.green, HeroCol.green, HeroCol.grey, HeroCol.orange, HeroCol.yellow}), Force(1.0F, new HeroCol[]{HeroCol.yellow, HeroCol.yellow, HeroCol.orange, HeroCol.grey, HeroCol.grey}), Magical(0.8F, new HeroCol[]{HeroCol.red, HeroCol.red, HeroCol.blue, HeroCol.green, HeroCol.orange}), Flex(0.7F, new HeroCol[]{HeroCol.green, HeroCol.yellow, null, HeroCol.blue, HeroCol.red}), Mountain(0.3F, new HeroCol[]{HeroCol.blue, HeroCol.blue, HeroCol.grey, HeroCol.grey, HeroCol.green}), Defensive(0.2F, new HeroCol[]{HeroCol.red, HeroCol.red, HeroCol.grey, HeroCol.grey, HeroCol.yellow}), RNG(0.2F, new HeroCol[]{null, null, null, null, null}), Strays(0.1F, new HeroCol[]{HeroCol.grey, HeroCol.orange, HeroCol.orange, null, null}), Cisab(0.1F, new HeroCol[]{HeroCol.blue, HeroCol.red, HeroCol.grey, HeroCol.yellow, HeroCol.orange}), Rush(0.05F, new HeroCol[]{HeroCol.blue, HeroCol.blue, HeroCol.orange, HeroCol.grey, HeroCol.yellow}), Surrounded(GAR(), new HeroCol[]{null, null, HeroCol.red, null, null}), DMLS(GAR(), new HeroCol[]{HeroCol.red, HeroCol.red, HeroCol.grey, HeroCol.red, HeroCol.red}), Sunset(GAR(), new HeroCol[]{HeroCol.blue, HeroCol.orange, HeroCol.yellow, null, HeroCol.green}), CornCob(GAR(), new HeroCol[]{HeroCol.yellow, HeroCol.yellow, HeroCol.yellow, HeroCol.yellow, HeroCol.yellow}), Beach(GAR(), new HeroCol[]{HeroCol.blue, HeroCol.blue, HeroCol.yellow, HeroCol.yellow, HeroCol.yellow}), Sword(GAR(), new HeroCol[]{HeroCol.orange, HeroCol.orange, HeroCol.grey, HeroCol.grey, HeroCol.grey}), LampPost(GAR(), new HeroCol[]{null, HeroCol.yellow, HeroCol.grey, HeroCol.grey, HeroCol.grey});
B3: Zones and enemies | C3: public enum Zone { Forest(0, new String[]{"archer", "goblin", "boar", "rat", "wolf", "grandma", "thorn", "seed", "bee", "log", "chest"}), Dungeon(1, new String[]{"shade", "snake", "goblin", "quartz", "ogre", "slate", "slimer", "cyclops", "warchief", "dragon egg", "chest", "Illusion", "sudul", "bandit", "barrel", "militia", "fountain", "blind"}), Catacombs(2, new String[]{"shade", "zombie", "z0mbie", "bones", "wizz", "fanatic", "sniper", "imp", "grave", "quartz", "ghost", "slimer", "spiker", "sudul", "chest", "Illusion", "banshee", "militia", "Carrier", "fountain"}), Lair(3, new String[]{"chomp", "basilisk", "sniper", "demon", "ghost", "alpha", "blind", "ogre", "spiker", "slate", "troll", "caw", "snake", "cyclops", "warchief", "caw egg", "hydra", "gnoll", "dragon egg", "bandit", "thorn", "Carrier", "log", "chest"}), Pit(4, new String[]{"chomp", "demon", "sniper", "zombie", "z0mbie", "wizz", "basilisk", "spiker", "troll", "caw", "hydra", "fanatic", "dragon egg", "wisp", "banshee", "barrel", "shade"}), Nightmare(5, new String[]{"deathsigil", "decaysigil", "painsigil", "z0mbie", "x2.basilisk", "x2.basalt", "x2.lich", "x2.goblin", "x2.inevitable", "x3.hexia", "x3.alpha", "x3.warchief", "x3.log", "x3.shade", "x4.dragon egg", "x4.sniper", "x4.snake", "x5.wolf", "x5.the hand", "x6.sudul", "x6.dragon", "x7.bones", "x8.illusion", "x8.troll king", "x9.thorn", "x9.slate"}), Snow(-1, new String[]{"archer", "goblin", "boar", "rat", "wolf", "grandma", "thorn", "seed", "bee", "log"}), Ice(-1, new String[]{"archer", "goblin", "boar", "rat", "wolf", "grandma", "thorn", "seed", "bee", "log"}), All(-1, MonsterTypeLib.stringArray(MonsterTypeLib.getAllValidMonsters()));
B4: Items part 1 | C4: private static List<ItBill> makeOneToFive() { return Arrays.asList((new ItBill(1, "Arrow")).trigger(new AffectSides(new TypeCondition(EffType.Damage), new AffectSideEffect[]{new ReplaceWith(new EntSide[]{ESB.headshot.val(2)})})), (new ItBill(1, "Memory")).trigger(new AffectSides(SpecificSidesType.Left, new AffectSideEffect[]{new ReturnToInnate()})), (new ItBill(1, "Balisong")).trigger(new AffectSides(SpecificSidesType.Left, new AffectSideEffect[]{new ReplaceWith(new EntSide[]{ESB.dmgCantrip.val(1)})})), (new ItBill(1, "Corset")).trigger(new AffectSides(SpecificSidesType.LeftTwo, new AffectSideEffect[]{new AffectByIndex(new AffectSideEffect[]{new ReplaceWithBlank(ChoosableType.Item), new FlatBonus(1)})})), (new ItBill(1, "Tankard")).trigger(SpecificSidesType.Middle, new AddKeyword(new Keyword[]{Keyword.acidic})), (new ItBill(1, "Doll")).trigger(new AffectSides(SpecificSidesType.Left, new AffectSideEffect[]{new CopyBaseFromHeroAbove(true)})).trigger(new AffectSides(SpecificSidesType.RightFive, new AffectSideEffect[]{new FlatBonus(-1)})), (new ItBill(1, "Wand of Wand")).trigger(new AffectSides(SpecificSidesType.Middle, new AffectSideEffect[]{new ReplaceWith(new EntSide[]{ESB.wandOfWand.val(1)})})), (new ItBill(1, "Sorcery Notes")).trigger(new AffectSides(SpecificSidesType.LeftTwo, new AffectSideEffect[]{new ReplaceWith(new EntSide[]{ESB.manaCantrip.val(1), ESB.blankItem})})), (new ItBill(1, "Quiver")).trigger(new AffectSides(SpecificSidesType.RightFive, new AffectSideEffect[]{new ReplaceWith(new EntSide[]{ESB.arrow.val(1)})})), (new ItBill(1, "Revive Potion")).trigger(new AffectSides(SpecificSidesType.Right, new AffectSideEffect[]{new ReplaceWith(new EntSide[]{ESB.potionRevive.val(5)})})), (new ItBill(1, "Courage Potion")).trigger(new AffectSides(SpecificSidesType.Left, new AffectSideEffect[]{new AddKeyword(new Keyword[]{Keyword.potion}), new FlatBonus(3)})), (new ItBill(1, "Pendulum")).trigger(new AffectSides(new AffectSideEffect[]{new SwapSides(SpecificSidesType.Left, SpecificSidesType.Middle)})), (new ItBill(1, "Tattered Robes")).trigger(new AffectSides(SpecificSidesType.RightThree, new AffectSideEffect[]{new ReplaceWith(new EntSide[]{ESB.mana.val(1), ESB.mana.val(1), ESB.mana.val(1)})})).trigger(new TriggerPersonalToGlobal(new GlobalMaxMana(1))), (new ItBill(1, "Leather Vest")).trigger(new MaxHP(1)), (new ItBill(1, "Healing Wand")).trigger(new AffectSides(SpecificSidesType.RightMost, new AffectSideEffect[]{new ReplaceWith(new EntSide[]{ESB.wandHeal.val(4)})})), (new ItBill(1, "Castor Root")).trigger(new AffectSides(new TypeCondition(EffType.Blank), new AffectSideEffect[]{new ReplaceWith(new EntSide[]{ESB.heal.val(1)})})), (new ItBill(1, "Seedling")).trigger(new AffectSides(SpecificSidesType.Left, new AffectSideEffect[]{new ReplaceWith(new EntSide[]{ESB.damageGrowth.val(2)})})), (new ItBill(1, "Reagents")).trigger(new AffectSides(SpecificSidesType.RightTwo, new AffectSideEffect[]{new ReplaceWith(new EntSide[]{ESB.blankItem, ESB.healRegen.val(1)})})), (new ItBill(1, "Rusty Plate")).trigger(new AffectSides(SpecificSidesType.Middle, new AffectSideEffect[]{new ReplaceWith(new EntSide[]{ESB.blankItem})})).trigger(new MaxHP(3)), (new ItBill(1, "Anchor")).trigger(new StartOfCombat((new EffBill()).shield(2).self().bEff())), (new ItBill(1, "Big Shield")).trigger(new AffectSides(SpecificSidesType.Left, new AffectSideEffect[]{new ReplaceWith(new EntSide[]{ESB.shield.val(4)})})), (new ItBill(1, "Cloak")).trigger(new AffectSides(SpecificSidesType.Middle, new AffectSideEffect[]{new ReplaceWith(new EntSide[]{ESB.dodge})})), (new ItBill(1, "Scar")).trigger(new EmptyPips(5)), (new ItBill(1, "Ballet Shoes")).trigger(new AffectSides(new AffectSideEffect[]{new SwapSides(SpecificSidesType.Left, SpecificSidesType.RightMost)})), (new ItBill(1, "Titanbane Potion")).trigger(new AffectSides(SpecificSidesType.Middle, new AffectSideEffect[]{new AddKeyword(new Keyword[]{Keyword.dispel, Keyword.potion})})), (new ItBill(1, "Change of Heart")).trigger(new AffectSides(new TypeCondition(EffType.Heal), new AffectSideEffect[]{new ChangeType(ESB.shield, "basic shield")})), (new ItBill(1, "Emerald Shard")).trigger(new CopyAlliedItems(2)), (new ItBill(1, "Barkskin")).trigger(new ShieldImmunity()).trigger(new MaxHP(2)), (new ItBill(1, "Knife Bag")).trigger(new AffectSides(new TypeCondition(EffType.Blank), new AffectSideEffect[]{new ReplaceWith(new EntSide[]{ESB.dmgCantrip.val(1).withKeyword(Keyword.pain)})})), (new ItBill(1, "Big Heart")).trigger(new AffectSides(SpecificSidesType.Middle, new AffectSideEffect[]{new ReplaceWith(new EntSide[]{ESB.heal.val(7)})})), (new ItBill(1, "Compass")).trigger(new AffectSides(new AffectSideEffect[]{new Rotate()})), (new ItBill(1, "Bone Charm")).trigger(new AvoidDeathPenalty()), (new ItBill(1, "Infused Herbs")).trigger(new AffectSides(SpecificSidesType.Bot, new AffectSideEffect[]{new ReplaceWith(new EntSide[]{ESB.infusedHerbs.val(2)})})), new ItBill(1, (new SpellBill()).title("Poultice").cost(1).eff((new EffBill()).heal(2).keywords(new Keyword[]{Keyword.singleCast}))), (new ItBill(1, "Cheating Sleeves")).trigger(new AffectSides(SpecificSidesType.Wings, new AffectSideEffect[]{new AddKeyword(new Keyword[]{Keyword.quin})})), (new ItBill(1, "Copper Ring")).trigger(new EmptyPips(1)).trigger(new TriggerPersonalToGlobal(new GlobalMaxMana(1))), (new ItBill(1, "Wolf Ears")).trigger(new MaxHpSet(6)), (new ItBill(1, "Basilisk Scale")).trigger(new StartPetrified(1)).trigger(new AffectSides(SpecificSidesType.Top, new AffectSideEffect[]{new FlatBonus(3)})), (new ItBill(1, "Glass Helm")).trigger(new MaxHP(3)).trigger(new Permadeath()), (new ItBill(1, "Iron Heart")).trigger(new AffectSides(new AffectSideEffect[]{new AddKeyword(new Keyword[]{Keyword.exert}), new FlatBonus(1)})), (new ItBill(1, "Bowl")).trigger(new AffectSides(SpecificSidesType.Column, new AffectSideEffect[]{new ReturnToInnate()})), (new ItBill(1, "Coin")).trigger(new AffectSides(SpecificSidesType.Left, new AffectSideEffect[]{new FlatBonus(4)})).trigger(new TriggerPersonalToGlobal(new GlobalBonusRerolls(-1))), (new ItBill(1, "Trowel")).trigger(new AffectSides(SpecificSidesType.Left, new AffectSideEffect[]{new ReplaceWith(new EntSide[]{ESB.resurrect.val(1)})})), (new ItBill(1, "Doom Blade")).trigger(new AffectSides(new TypeCondition(EffType.Blank), new AffectSideEffect[]{new ReplaceWith(new EntSide[]{ESB.dmgDeath.val(3)})})), (new ItBill(1, "Tincture")).trigger(new AffectSides(SpecificSidesType.RightMost, new AffectSideEffect[]{new AddKeyword(new Keyword[]{Keyword.cleanse})})), (new ItBill(1, "Whey")).trigger(new AffectSides(SpecificSidesType.Left, new AffectSideEffect[]{new AddKeyword(new Keyword[]{Keyword.vitality})})), (new ItBill(1, "Necromancer Tome")).trigger(new TriggerPersonalToGlobal(new GlobalAllowDeadHeroSpells())).trigger(new AffectSides(SpecificSidesType.Left, new AffectSideEffect[]{new ReplaceWith(new EntSide[]{ESB.manaPain.val(3)})})), (new ItBill(1, "Clumsy Shoes")).trigger(new AffectSides(new TargetedCondition(), new AffectSideEffect[]{new AddKeyword(new Keyword[]{Keyword.heavy, Keyword.eliminate}), new FlatBonus(1)})), new ItBill(2, (new SpellBill()).cost(2).title("Wings").eff((new EffBill()).heal(3).targetType(TargetingType.TopAndBot))), (new ItBill(2, "Needle")).trigger(new AffectSides(new TargetedCondition(), new AffectSideEffect[]{new AddKeyword(new Keyword[]{Keyword.picky}), new FlatBonus(2)})), (new ItBill(2, "Ice Cube")).trigger(new AffectSides(SpecificSidesType.Left, new AffectSideEffect[]{new AddKeyword(new Keyword[]{Keyword.stasis})})), (new ItBill(2, "Worn Arms")).trigger(new AffectSides(SpecificSidesType.Wings, new AffectSideEffect[]{new ReplaceWith(new EntSide[]{ESB.dmg.val(2), ESB.shield.val(2)})})), (new ItBill(2, "Foil")).trigger(new AffectSides(SpecificSidesType.Right, new AffectSideEffect[]{new ReplaceWith(new EntSide[]{ESB.dmg.val(0).withKeyword(Keyword.skill)})})), (new ItBill(2, "Kilt")).trigger(new CopySide(SpecificSidesType.Right, SpecificSidesType.RightMost)), (new ItBill(2, "Static Tome")).trigger(new AffectSides(SpecificSidesType.Wings, new AffectSideEffect[]{new ReplaceWith(new EntSide[]{ESB.manaPair.val(1)})})), (new ItBill(2, "Polearm")).trigger(new AffectSides(new TypeCondition(EffType.Damage), new AffectSideEffect[]{new ChangeToMyPosition(SpecificSidesType.Top)})), (new ItBill(2, "Flickering Blade")).trigger(new AffectSides(SpecificSidesType.RightMost, new AffectSideEffect[]{new ReplaceWith(new EntSide[]{ESB.dmgCopycat.val(1)})})), (new ItBill(2, "Origami")).trigger(new AffectSides(new AffectSideEffect[]{new Flip()})), (new ItBill(2, "Statuette")).trigger(new AffectSides(SpecificSidesType.Row, new AffectSideEffect[]{new ReplaceWith(new EntSide[]{ESB.blankItem})})).trigger(new MaxHP(6)), (new ItBill(2, "Spinach")).trigger(new StartOfCombat((new EffBill()).heal(3).self().bEff())), (new ItBill(2, "Buckler")).trigger(new AffectSides(SpecificSidesType.Middle, new AffectSideEffect[]{new ReplaceWith(new EntSide[]{ESB.shield.val(3).withKeyword(Keyword.bloodlust)})})), (new ItBill(2, "Sapphire")).trigger(new AffectSides(SpecificSidesType.Middle, new AffectSideEffect[]{new ReplaceWith(new EntSide[]{ESB.mana.val(2)})})), (new ItBill(2, "Ace of Spades")).trigger(new AffectSides(SpecificSidesType.All, new AffectSideEffect[]{new AffectByIndex(new AffectSideEffect[]{new FlatBonus(2), new FlatBonus(-2), new FlatBonus(-2), new FlatBonus(-2), new FlatBonus(-2), new FlatBonus(-2)})})), (new ItBill(2, "Garnet")).trigger(new IncomingEffBonus(1, new EffType[]{EffType.Heal})), (new ItBill(2, "Powdered Mana")).trigger(new AffectSides(new TypeCondition(EffType.Blank), new AffectSideEffect[]{new ReplaceWith(new EntSide[]{ESB.mana.val(1)})})), (new ItBill(2, "Burning Blade")).trigger(new AffectSides(SpecificSidesType.Left, new AffectSideEffect[]{new ReplaceWith(new EntSide[]{ESB.dmg.val(4)})})).trigger(new MaxHP(-2)), (new ItBill(2, "Citrine Ring")).trigger(new AffectSides(SpecificSidesType.RightMost, new AffectSideEffect[]{new FlatBonus(1)})), (new ItBill(2, "Big Hammer")).trigger(new AffectSides(SpecificSidesType.LeftTwo, new AffectSideEffect[]{new ReplaceWith(new EntSide[]{ESB.dmgHeavy.val(5), ESB.blankItem})})), (new ItBill(2, "Autumn Leaf")).trigger(new AffectSides(SpecificSidesType.RightMost, new AffectSideEffect[]{new AddKeyword(new Keyword[]{Keyword.growth})})), (new ItBill(2, "Blessed Water")).trigger(new AffectSides(SpecificSidesType.Middle, new AffectSideEffect[]{new ReplaceWith(new EntSide[]{ESB.healVitality.val(3)})})), (new ItBill(2, "Blessed Ring")).trigger(new AffectSides(SpecificSidesType.RightMost, new AffectSideEffect[]{new ReplaceWith(new EntSide[]{ESB.shieldRescue.val(1)})})), (new ItBill(2, "Twin Daggers")).trigger(new AffectSides(SpecificSidesType.Wings, new AffectSideEffect[]{new ReplaceWith(new EntSide[]{ESB.dmgCantrip.val(1)})})), (new ItBill(2, "Rain of Arrows")).trigger(new AffectSides(SpecificSidesType.Top, new AffectSideEffect[]{new ReplaceWith(new EntSide[]{ESB.arrowDuplicate.val(1)})})), (new ItBill(2, "Liqueur")).trigger(new AffectSides(new AffectSideEffect[]{new SwapSides(SpecificSidesType.Top, SpecificSidesType.RightMost)})).trigger(new TriggerPersonalToGlobal(new GlobalMaxMana(2))), (new ItBill(2, "Peaked Cap")).trigger(new CopySide(SpecificSidesType.Middle, SpecificSidesType.Left)), (new ItBill(2, "Sapphire Skull")).trigger(new OnDeathEffect((new EffBill()).mana(2).bEff(), new ManaGainEvent(2, "Sapphire Skull"))), (new ItBill(2, "First aid Kit")).trigger(new EquipRestrictCol(HeroCol.orange)).trigger(new AffectSides(SpecificSidesType.Bot, new AffectSideEffect[]{new ReplaceWith(new EntSide[]{ESB.healCleanse.val(2)})})), (new ItBill(2, "Friendship Bracelet")).trigger(new EmptyPips(2)).trigger(new TriggerPersonalToGlobal(new GlobalFleeAt(5), "friendship")), (new ItBill(2, "Clumsy Hammer")).trigger(new AffectSides(SpecificSidesType.Top, new AffectSideEffect[]{new ReplaceWith(new EntSide[]{ESB.dmgHeavy.val(4).withKeyword(Keyword.eliminate)})})), (new ItBill(2, "Tower Shield")).trigger(new AffectSides(SpecificSidesType.Middle, new AffectSideEffect[]{new ReplaceWith(new EntSide[]{ESB.shield.val(7).withKeyword(Keyword.heavy)})})), (new ItBill(2, "Square Wheel")).trigger(new AffectSides(SpecificSidesType.RightThree, new AffectSideEffect[]{new ReplaceWith(new EntSide[]{ESB.rerollCantrip.val(1), ESB.blankItem, ESB.blankItem})})), (new ItBill(2, "Silver Imp")).confirmed().trigger(new AffectSides(SpecificSidesType.Wings, new AffectSideEffect[]{new ReplaceWith(new EntSide[]{ESB.rerollCantrip.val(1).withKeyword(Keyword.pain)})})), (new ItBill(2, "Fletching")).trigger(new AffectSides(SpecificSidesType.Left, new AffectSideEffect[]{new AddKeyword(new Keyword[]{Keyword.ranged})})), (new ItBill(2, "Wandify")).trigger(new AffectSides(SpecificSidesType.RightTwo, new AffectSideEffect[]{new AddKeyword(new Keyword[]{Keyword.singleUse}), new FlatBonus(1)})), (new ItBill(2, "Leather Gloves")).trigger(new CopySide(SpecificSidesType.RightMost, SpecificSidesType.Wings)), new ItBill(2, (new SpellBill()).cost(1).title("remedy").eff((new EffBill()).heal(1).visual(VisualEffectType.HealBasic).keywords(new Keyword[]{Keyword.cleanse, Keyword.singleCast}))), (new ItBill(2, "Golden Thread")).trigger(new EquipRestrictCol(HeroCol.yellow)).trigger(new AffectSides(new NotCondition(new TypeCondition(EffType.Damage)), new AffectSideEffect[]{new FlatBonus(1)})), (new ItBill(2, "Clef")).trigger(new AffectSides(SpecificSidesType.Left, new AffectSideEffect[]{new AddKeyword(new Keyword[]{Keyword.treble})})), (new ItBill(2, "Rejuvenation Wand")).trigger(new AffectSides(SpecificSidesType.Wings, new AffectSideEffect[]{new ReplaceWith(new EntSide[]{ESB.wandHeal.val(10)})})), (new ItBill(2, "Quicksilver")).trigger(new KeepShields()), (new ItBill(2, "Pillow")).confirmed().trigger(new AffectSides(SpecificSidesType.Left, new AffectSideEffect[]{new AddKeyword(new Keyword[]{Keyword.patient})})), (new ItBill(2, "Faint Halo")).confirmed().trigger(new OnRescue((new EffBill()).self().buff(new Buff(new MaxHP(1))).bEff())), (new ItBill(2, "Terrarium")).trigger(new AffectSides(SpecificSidesType.RightTwo, new AffectSideEffect[]{new ReplaceWith(new EntSide[]{ESB.shieldGrowth.val(2), ESB.manaGrowth.val(1)})})), new ItBill(3, (new SpellBill()).title("Flare").cost(4).eff((new EffBill()).damage(5).visual(VisualEffectType.Flame))), (new ItBill(3, "Shortsword")).trigger(new AffectSides(SpecificSidesType.RightTwo, new AffectSideEffect[]{new ReplaceWith(new EntSide[]{ESB.dmg.val(2)})})), (new ItBill(3, "Longbow")).trigger(new AffectSides(SpecificSidesType.Wings, new AffectSideEffect[]{new ReplaceWith(new EntSide[]{ESB.arrow.val(2)})})), (new ItBill(3, "Incense")).trigger(new AffectSides(SpecificSidesType.Top, new AffectSideEffect[]{new AddKeyword(new Keyword[]{Keyword.rite})})), (new ItBill(3, "Juice")).trigger(new AffectSides(SpecificSidesType.Left, new AffectSideEffect[]{new AddKeyword(new Keyword[]{Keyword.selfCleanse})})), (new ItBill(3, "Golden Cup")).trigger(new EmptyPips(100)).trigger(new TriggerPersonalToGlobal(new GlobalMaxMana(100))), (new ItBill(3, "Wristblade")).trigger(new AffectSides(new TypeCondition(EffType.Blank), new AffectSideEffect[]{new ReplaceWith(new EntSide[]{ESB.dmgDouble.val(1)})})), (new ItBill(3, "Ash")).trigger(new AffectSides(SpecificSidesType.MiddleTwo, new AffectSideEffect[]{new AddKeyword(new Keyword[]{Keyword.enduring})})), (new ItBill(3, "Pure Heart Pendant")).trigger(new AffectSides(SpecificSidesType.Middle, new AffectSideEffect[]{new ReplaceWith(new EntSide[]{ESB.healCleanse.val(3)})})), new ItBill(3, (new SpellBill()).cost(3).title("sprout").eff((new EffBill()).heal(3).keywords(new Keyword[]{Keyword.channel}).visual(VisualEffectType.HealBasic))), (new ItBill(3, "Scalpel")).trigger(new EquipRestrictCol(HeroCol.red)).trigger(new AffectSides(new TypeCondition(EffType.Damage), new AffectSideEffect[]{new FlatBonus(1)})), (new ItBill(3, "Lead Boots")).trigger(new AffectSides(new AffectSideEffect[]{new AddKeyword(new Keyword[]{Keyword.sticky}), new FlatBonus(1)})), (new ItBill(3, "Abacus")).trigger(new AffectSides(new AffectSideEffect[]{new Shift()})).trigger(new MaxHP(1)), (new ItBill(3, "Lightning Rod")).trigger(new AffectSides(SpecificSidesType.Left, new AffectSideEffect[]{new ReplaceWith(new EntSide[]{ESB.dmgRangedRampage.val(0)})})), (new ItBill(3, "Iron Pendant")).trigger(new IncomingEffBonus(1, new EffType[]{EffType.Shield})), (new ItBill(3, "Droopy Hat")).trigger(new MaxHP(2)).trigger(new TriggerPersonalToGlobal(new GlobalMaxMana(2))), (new ItBill(3, "Enchanted Shield")).trigger(new StartOfTurnSelf(new Eff[]{(new EffBill()).shield(1).self().bEff()})), (new ItBill(3, "Whetstone")).trigger(new AffectSides(new TypeCondition(EffType.Damage, true), new AffectSideEffect[]{new FlatBonus(1)})), (new ItBill(3, "Pocket Phylactery")).trigger(new AffectSides(SpecificSidesType.LeftTwo, new AffectSideEffect[]{new AddKeyword(new Keyword[]{Keyword.pain})})).trigger(new MaxHP(6)), (new ItBill(3, "Ladder")).trigger(new AffectSides(SpecificSidesType.Middle, new AffectSideEffect[]{new CopyBaseFromHeroAbove(true)})), (new ItBill(3, "Magnet")).trigger(new AffectSides(SpecificSidesType.RightTwo, new AffectSideEffect[]{new AddKeyword(new Keyword[]{Keyword.wham})})), (new ItBill(3, "Blood Chalice")).trigger(new OnOverheal((new EffBill()).shield(1).self())), (new ItBill(3, "Smelly Manure")).trigger(new AffectSides(new SpecificSidesCondition(SpecificSidesType.All), new AffectSideEffect[]{new AffectByIndex(new AffectSideEffect[]{new AddKeyword(new Keyword[]{Keyword.decay}), new AddKeyword(new Keyword[]{Keyword.decay}), new AddKeyword(new Keyword[]{Keyword.growth}), new AddKeyword(new Keyword[]{Keyword.growth}), new AddKeyword(new Keyword[]{Keyword.decay}), new AddKeyword(new Keyword[]{Keyword.decay})})})), (new ItBill(3, "Lich Finger")).trigger(new AffectSides(SpecificSidesType.Left, new AffectSideEffect[]{new AddKeyword(new Keyword[]{Keyword.manaGain, Keyword.death})})), (new ItBill(3, "Unholy Strength")).trigger(new ShieldImmunity()).trigger(new HealImmunity()).trigger(new AffectSides(SpecificSidesType.Row, new AffectSideEffect[]{new FlatBonus(1)})), (new ItBill(3, "Three of a Kind")).trigger(new AffectSides(SpecificSidesType.RightMost, new AffectSideEffect[]{new AddKeyword(new Keyword[]{Keyword.trio})})), (new ItBill(3, "Clover")).trigger(new AffectSides(SpecificSidesType.LeftTwo, new AffectSideEffect[]{new FlatBonus(new int[]{1, -2})})), (new ItBill(3, "Diving Suit")).trigger(new AffectSides(SpecificSidesType.RightTwo, new AffectSideEffect[]{new CopyBaseFromHeroAbove(false)})), (new ItBill(3, "Poem")).trigger(new AffectSides(new TypeCondition(EffType.Damage), new AffectSideEffect[]{new AddKeyword(new Keyword[]{Keyword.alliteration})})), (new ItBill(3, "Syringe")).trigger(new PersonalConditionLink(new SnapshotCondition(SnapshotConditionType.OrFewerHeroes, 2), new AffectSides(new AffectSideEffect[]{new AddKeyword(new Keyword[]{Keyword.cantrip})}))), (new ItBill(3, "Aegis")).trigger(new AffectSides(SpecificSidesType.Middle, new AffectSideEffect[]{new ReplaceWith(new EntSide[]{ESB.shieldDuplicate.val(1).withKeyword(Keyword.steel)})})), (new ItBill(3, "Duvet")).trigger(new AffectSides(SpecificSidesType.RightThree, new AffectSideEffect[]{new AddKeyword(new Keyword[]{Keyword.patient})})), (new ItBill(3, "Siphon")).trigger(new AffectSides(new TypeCondition(EffType.Mana), new AffectSideEffect[]{new AddKeyword(new Keyword[]{Keyword.pain}), new FlatBonus(1)})), (new ItBill(3, "Ritual Dagger")).trigger(new AffectSides(SpecificSidesType.RightMost, new AffectSideEffect[]{new ReplaceWith(new EntSide[]{ESB.resurrect.val(4).withKeyword(Keyword.death)})})), (new ItBill(3, "Harpoon")).trigger(new AffectSides(SpecificSidesType.RightMost, new AffectSideEffect[]{new ReplaceWith(new EntSide[]{ESB.dmgVuln.val(1)})})), (new ItBill(3, "Wild Seeds")).trigger(new AffectSides(SpecificSidesType.LeftTwo, new AffectSideEffect[]{new AddKeyword(new Keyword[]{Keyword.undergrowth})})), (new ItBill(3, "Mana Bomb")).trigger(new AffectSides(SpecificSidesType.RightMost, new AffectSideEffect[]{new ReplaceWith(new EntSide[]{ESB.manaBomb.val(0)})})), (new ItBill(3, "Viscera")).trigger(new AffectSides(SpecificSidesType.Middle, new AffectSideEffect[]{new ReplaceWith(new EntSide[]{ESB.dmgFleshPain.val(0)})})), new ItBill(3, (new SpellBill()).cost(3).title("heat").eff((new EffBill()).keywords(new Keyword[0]).group().heal(3).keywords(new Keyword[]{Keyword.cleanse}).restrict(StateConditionType.HasShields))), (new ItBill(4, "Relic")).trigger(new AddKeyword(new Keyword[]{Keyword.swapTerminal})), (new ItBill(4, "Corruption")).trigger(new AffectSides(new TypeCondition(EffType.Heal), new AffectSideEffect[]{new AddKeyword(new Keyword[]{Keyword.evil}), new FlatBonus(1)})), (new ItBill(4, "Pulley")).trigger(new AffectSides(new AffectSideEffect[]{new Shift(false)})).trigger(new ItemSlots(2)), new ItBill(4, (new SpellBill()).cost(4).title("Mark").eff((new EffBill()).damage(2).keywords(new Keyword[]{Keyword.vulnerable}).visual(VisualEffectType.Slice))), (new ItBill(4, "Chakram")).trigger(new AffectSides(new TypeCondition(EffType.Shield), new AffectSideEffect[]{new ChangeType(ESB.arrow, "ranged damage")})), (new ItBill(4, "Cracked Plate")).trigger(new MaxHP(-4)).trigger(new StartOfTurnSelf(new Eff[]{(new EffBill()).shield(4).self().bEff()})), (new ItBill(4, "Splitting Arrows")).trigger(new AffectSides(SpecificSidesType.RightTwo, new AffectSideEffect[]{new ReplaceWith(new EntSide[]{ESB.arrowCleave.val(1)})})), (new ItBill(4, "Hissing Ring")).trigger(new AffectSides(SpecificSidesType.Middle, new AffectSideEffect[]{new ReplaceWith(new EntSide[]{ESB.dmgPoison.val(2)})})), (new ItBill(4, "Magic Staff")).trigger(new AffectSides(new TypeCondition(EffType.Mana), new AffectSideEffect[]{new SetValue(2)})), (new ItBill(4, "Obol")).trigger(new AffectSides(SpecificSidesType.RightTwo, new AffectSideEffect[]{new AddKeyword(new Keyword[]{Keyword.deathwish})})), (new ItBill(4, "Demon Eye")).trigger(new AffectSides(SpecificSidesType.Left, new AffectSideEffect[]{new AddKeyword(new Keyword[]{Keyword.pain}), new FlatBonus(2)})), (new ItBill(4, "Idol of Aiiu")).trigger(new HpBonusLetter(1, HpBonusLetter.VOWELS)), (new ItBill(4, "Glass Blade")).trigger(new AffectSides(SpecificSidesType.Left, new AffectSideEffect[]{new ReplaceWith(new EntSide[]{ESB.dmg.val(5)})})).trigger(new LostOnDeath("Glass Blade")), new ItBill(4, (new SpellBill()).cost(2).title("hack").eff((new EffBill()).replaceBlanksWith(ESB.dmg.val(4)))), (new ItBill(4, "Antivenom")).trigger(new DamageImmunity(true, false)), (new ItBill(4, "Chainmail")).trigger(new MaxHP(3)), new ItBill(4, (new SpellBill()).cost(3).title("hex").eff((new EffBill()).kill().value(6).keywords(new Keyword[]{Keyword.ranged, Keyword.singleCast}).restrict(new ConditionalRequirement[]{TargetingRestriction.ExactlyValue}).visual(VisualEffectType.Cross).value(6))), new ItBill(4, (new SpellBill()).cost(4).title("invest").eff((new EffBill()).mana(6).keywords(new Keyword[]{Keyword.future, Keyword.cooldown}))), (new ItBill(4, "Life Bolt")).trigger(new AfterUseAbility((Integer)null, (new EffBill()).heal(1).self().bEff())), (new ItBill(4, "Soup")).trigger(new AffectSides(new TypeCondition(EffType.Shield), new AffectSideEffect[]{new ChangeType(ESB.healShield, "heal and shield")})), (new ItBill(4, "Tiara")).trigger(new AffectSides(new TypeCondition(EffType.Mana), new AffectSideEffect[]{new AddKeyword(new Keyword[]{Keyword.selfHeal})})), (new ItBill(4, "Charged Skull")).trigger(new OnDeathEffect((new EffBill()).mana(4).bEff(), new ManaGainEvent(4, "Charged Skull"))), (new ItBill(4, "Apple")).trigger(new AffectSides(SpecificSidesType.LeftTwo, new AffectSideEffect[]{new AddKeyword(new Keyword[]{Keyword.ego})})), (new ItBill(4, "Mana Jelly")).trigger(new AffectSides(new TypeCondition(EffType.Mana), new AffectSideEffect[]{new AddKeyword(new Keyword[]{Keyword.singleUse, Keyword.cantrip})})), (new ItBill(4, "Jester Cap")).trigger(new AffectSides(SpecificSidesType.All, new AffectSideEffect[]{new ReplaceWithEnt(HeroTypeUtils.byName("jester"))})), (new ItBill(4, "Natural")).trigger(new EquipRestrictCol(HeroCol.blue)).trigger(new AffectSides(SpecificSidesType.RightTwo, new AffectSideEffect[]{new ReplaceWith(new EntSide[]{ESB.mana.val(2)})})), (new ItBill(4, "Updog")).trigger(new AffectSides(SpecificSidesType.Top, new AffectSideEffect[]{new AddKeyword(new Keyword[]{Keyword.overdog})})), (new ItBill(4, "Flawed Diamond")).trigger(new AffectSides(SpecificSidesType.LeftTwo, new AffectSideEffect[]{new AddKeyword(new Keyword[]{Keyword.pristine})})).trigger(new EmptyPips(4)), (new ItBill(4, "Duelling Pistol")).trigger(new AffectSides(SpecificSidesType.Left, new AffectSideEffect[]{new AddKeyword(new Keyword[]{Keyword.duel})})), (new ItBill(4, "Ink Bottle")).trigger(new AffectSides(new TypeCondition(EffType.Blank), new AffectSideEffect[]{new ReplaceWith(new EntSide[]{ESB.shieldCantrip.val(1)})})), (new ItBill(4, "Eyepatch")).trigger(new AffectSides(SpecificSidesType.Left, new AffectSideEffect[]{new RemoveAllKeywords()})), (new ItBill(4, "PowerStone")).trigger(new EquipRestrictCol(HeroCol.grey)).trigger(new AffectSides(SpecificSidesType.Middle, new AffectSideEffect[]{new ReplaceWith(new EntSide[]{ESB.mana.val(0).withKeyword(Keyword.steel)})})), (new ItBill(4, "Red flag")).trigger(new MaxHP(3)).trigger(new AffectSides(SpecificSidesType.Middle, new AffectSideEffect[]{new ReplaceWith(new EntSide[]{ESB.redFlag})})), (new ItBill(4, "Inner Strength")).trigger(new AffectSides(new AffectSideEffect[]{new RemoveKeywordColour(new Color[]{Colours.red, Colours.purple})})), (new ItBill(4, "Alembic")).trigger(new AffectSides(SpecificSidesType.Middle, new AffectSideEffect[]{new ReplaceWith(new EntSide[]{ESB.giveManaGainPain})})), (new ItBill(4, "Bonesaw")).trigger(new EquipRestrictCol(HeroCol.red)).trigger(new AffectSides(SpecificSidesType.Wings, new AffectSideEffect[]{new ReplaceWith(new EntSide[]{ESB.dmgCruel.val(3)})})), (new ItBill(4, "Full Moon")).trigger(new PersonalTurnRequirement(new TurnRequirementEveryN(2), new AffectSides(SpecificSidesType.All, new AffectSideEffect[]{new ReplaceWithEnt(MonsterTypeLib.byName("wolf"))}))), (new ItBill(4, "Shuriken")).trigger(new AffectSides(SpecificSidesType.RightTwo, new AffectSideEffect[]{new AddKeyword(new Keyword[]{Keyword.ranged, Keyword.chain})})), (new ItBill(4, "Troll Nose")).trigger(new StartRegenned(1)), (new ItBill(4, "Dragonhide Gloves")).trigger(new CopySide(SpecificSidesType.Middle, SpecificSidesType.Wings)), (new ItBill(4, "Glowing Egg")).trigger(new AffectSides(SpecificSidesType.Left, new AffectSideEffect[]{new AddKeyword(new Keyword[]{Keyword.growth})})), (new ItBill(4, "Eggshell")).trigger(new AffectSides(new AffectSideEffect[]{new AddKeyword(new Keyword[]{Keyword.zeroed})})), (new ItBill(4, "Whiskers")).trigger(new AffectSides(SpecificSidesType.RightThree, new AffectSideEffect[]{new ReplaceWith(new EntSide[]{ESB.arrowCopycat.val(1), ESB.dmgCopycat.val(1), ESB.shieldCopycat.val(1)})})), (new ItBill(4, "Faerie Pact")).trigger(new AffectSides(SpecificSidesType.RightMost, new AffectSideEffect[]{new ReplaceWith(new EntSide[]{ESB.mana.val(4)})})).trigger(new MaxHP(-4)), (new ItBill(4, "Fangs")).trigger(new AffectSides(SpecificSidesType.Left, new AffectSideEffect[]{new AddKeyword(new Keyword[]{Keyword.selfHeal})})), (new ItBill(4, "Cart")).trigger(new TriggerPersonalToGlobal(new GlobalHeroes(new ItemSlots(1)))).trigger(new ItemSlots(-2)), new ItBill(4, (new SpellBill()).title("beam").cost(5).eff((new EffBill()).damage(7).keywords(new Keyword[]{Keyword.singleCast, Keyword.ranged}).visual(VisualEffectType.Beam))), (new ItBill(4, "Dynamo")).trigger(new AffectSides(SpecificSidesType.RightTwo, new AffectSideEffect[]{new AddKeyword(new Keyword[]{Keyword.singleUse, Keyword.era})})), (new ItBill(5, "Cracked Wheel")).trigger(new AffectSides(new AffectSideEffect[]{new AddKeyword(new Keyword[]{Keyword.sticky})})).trigger(new TriggerPersonalToGlobal(new GlobalBonusRerolls(1))), (new ItBill(5, "Cocoon")).trigger(new AffectSides(new AffectSideEffect[]{new AddKeyword(new Keyword[]{Keyword.era}), new FlatBonus(-1)})), (new ItBill(5, "Shimmering Halo")).confirmed().trigger(new OnRescue((new EffBill()).self().buff(new Buff(new MaxHP(2))).bEff())), (new ItBill(5, "Wand Grips")).trigger(new AffectSides(SpecificSidesType.Left, new AffectSideEffect[]{new AddKeyword(new Keyword[]{Keyword.singleUse}), new FlatBonus(2)})), (new ItBill(5, "Lens")).trigger(new AffectSides(new TypeCondition(EffType.Heal), new AffectSideEffect[]{new AddKeyword(new Keyword[]{Keyword.focus})})), (new ItBill(5, "Poodle")).trigger(new AffectSides(SpecificSidesType.Column, new AffectSideEffect[]{new AddKeyword(new Keyword[]{Keyword.dog})})), (new ItBill(5, "Decree")).trigger(new AffectSides(new AffectSideEffect[]{new AddKeyword(new Keyword[]{Keyword.dogma})})), (new ItBill(5, "Erythrocyte")).trigger(new AffectSides(SpecificSidesType.Middle, new AffectSideEffect[]{new ReplaceWith(new EntSide[]{ESB.shieldFlesh.val(0)})})), (new ItBill(5, "Mini Crossbow")).trigger(new AffectSides(SpecificSidesType.Top, new AffectSideEffect[]{new ReplaceWith(new EntSide[]{ESB.rangedEngage.val(2)})})), (new ItBill(5, "Crystallise")).trigger(new AffectSides(new AffectSideEffect[]{new AddKeyword(new Keyword[]{Keyword.stasis})})), (new ItBill(5, "Longsword")).trigger(new AffectSides(SpecificSidesType.Row, new AffectSideEffect[]{new ReplaceWith(new EntSide[]{ESB.dmg.val(3)})})), (new ItBill(5, "Demon Horn")).trigger(new AffectSides(SpecificSidesType.RightMost, new AffectSideEffect[]{new ReplaceWith(new EntSide[]{ESB.demonHorn.val(2)})})), (new ItBill(5, "Pauldron")).trigger(new AffectSides(SpecificSidesType.Wings, new AffectSideEffect[]{new FlatBonus(new int[]{2, -2})})), (new ItBill(5, "Sack of Mana")).trigger(new AffectSides(SpecificSidesType.Column, new AffectSideEffect[]{new ReplaceWith(new EntSide[]{ESB.blankItem, ESB.mana.val(4), ESB.blankItem})})), (new ItBill(5, "Enchanted Harp")).trigger(new AffectSides(SpecificSidesType.Middle, new AffectSideEffect[]{new ReplaceWith(new EntSide[]{ESB.shieldAll.val(2)})})), (new ItBill(5, "Ambrosia")).trigger(new AffectSides(SpecificSidesType.Left, new AffectSideEffect[]{new AddKeyword(new Keyword[]{Keyword.rescue})})), (new ItBill(5, "Fearless")).trigger(new MaxHP(1)).trigger(new AffectSides(SpecificSidesType.RightMost, new AffectSideEffect[]{new ReplaceWith(new EntSide[]{ESB.stun})})), (new ItBill(5, "Ordinary Triangle")).trigger(new AffectSides(new ExactlyCondition(3), new AffectSideEffect[]{new FlatBonus(1)})), (new ItBill(5, "Monocle")).trigger(new AffectSides(SpecificSidesType.Middle, new AffectSideEffect[]{new AddKeyword(new Keyword[]{Keyword.engage})})), (new ItBill(5, "Doomblade")).trigger(new AffectSides(new TypeCondition(EffType.Damage), new AffectSideEffect[]{new AddKeyword(new Keyword[]{Keyword.guilt}), new FlatBonus(1)})), (new ItBill(5, "Simplicity")).trigger(new AffectSides(new TypeCondition(Arrays.asList(EffType.Heal, EffType.Mana, EffType.Damage, EffType.Shield), true), new AffectSideEffect[]{new FlatBonus(1)})), (new ItBill(5, "Glyph of Purity")).trigger(new AffectSides(SpecificSidesType.Wings, new AffectSideEffect[]{new AddKeyword(new Keyword[]{Keyword.cleanse})})), (new ItBill(5, "Door")).trigger(new PersonalConditionLink(new SnapshotCondition(SnapshotConditionType.OrMoreMonsters, 4), new AffectSides(new TypeCondition(EffType.Shield), new AffectSideEffect[]{new FlatBonus(2)}))), (new ItBill(5, "Ruby")).trigger(new IncomingEffBonus(2, new EffType[]{EffType.Heal})).trigger(new EmptyPips(2)), (new ItBill(5, "Whiskey")).trigger(new MaxHP(3)).trigger(new EmptyPips(6)), (new ItBill(5, "Polished Emerald")).trigger(new CopyAlliedItems(2, 4)), (new ItBill(5, "Treasure Chest")).trigger(new AffectSides(SpecificSidesType.Left, new AffectSideEffect[]{new AddKeyword(new Keyword[]{Keyword.hoard, Keyword.singleUse})})), (new ItBill(5, "Sling")).trigger(new AffectSides(SpecificSidesType.Bot, new AffectSideEffect[]{new AddKeyword(new Keyword[]{Keyword.underdog})})), (new ItBill(5, "Shining Bow")).trigger(new AffectSides(new TypeCondition(EffType.Damage), new AffectSideEffect[]{new AddKeyword(new Keyword[]{Keyword.ranged})})), (new ItBill(5, "Sponge")).trigger(new OtherDeathEffect("Sponge", false, (new EffBill()).self().buff(new Buff(1, new AffectSides(new AffectSideEffect[]{new FlatBonus(1)}))))), (new ItBill(5, "Sceptre")).trigger(new AffectSides(SpecificSidesType.Left, new AffectSideEffect[]{new ReplaceWith(new EntSide[]{ESB.scepter.val(1)})})), (new ItBill(7, "Wine")).trigger(new StartPoisoned(1)).trigger(new TriggerPersonalToGlobal(new GlobalMonsters(new StartPoisoned(1))))); } }
B5: Items part 2 | C5: private static List<ItBill> makeSixToNine() { return Arrays.asList((new ItBill(5, "Gizmo")).trigger(SpecificSidesType.RightTwo, new AddKeyword(new Keyword[]{Keyword.shifter})), (new ItBill(5, "Nunchaku")).trigger(new AffectSides(SpecificSidesType.Wings, new AffectSideEffect[]{new AddKeyword(new Keyword[]{Keyword.chain})})), (new ItBill(5, "Early Grave")).trigger(new AffectSides(new OrMoreCondition(3), new AffectSideEffect[]{new AddKeyword(new Keyword[]{Keyword.pain, Keyword.cantrip})})), (new ItBill(5, "Bandana")).trigger(new AffectSides(new HasValue(false), new AffectSideEffect[]{new AddKeyword(new Keyword[]{Keyword.cantrip})})), (new ItBill(6, "Blindfold")).trigger(new AffectSides(new AffectSideEffect[]{new RemoveAllKeywords()})), (new ItBill(6, "Determination")).trigger(new PersonalTurnRequirement(new TurnRequirementFirst(), new Undying())), (new ItBill(6, "Leaden Handle")).trigger(new AffectSides(new TargetedCondition(), new AffectSideEffect[]{new AddKeyword(new Keyword[]{Keyword.heavy}), new FlatBonus(1)})), (new ItBill(6, "Urn")).trigger(new AffectSides(new AffectSideEffect[]{new AddKeyword(new Keyword[]{Keyword.enduring})})), (new ItBill(6, "Braids")).trigger(new CopySide(SpecificSidesType.Left, SpecificSidesType.Middle)), (new ItBill(6, "Kite Shield")).trigger(new AffectSides(new TypeCondition(EffType.Shield), new AffectSideEffect[]{new SetValue(3)})), (new ItBill(6, "Idol of Chrzktx")).trigger(new HpBonusLetter(1, HpBonusLetter.CONSONANTS)), (new ItBill(6, "Wedding Rings")).trigger(new AffectSides(new TypeCondition(EffType.Heal), new AffectSideEffect[]{new AddKeyword(new Keyword[]{Keyword.pair})})), (new ItBill(6, "Jewel Loupe")).trigger(new AffectSides(new ExactlyCondition(1), new AffectSideEffect[]{new AddKeyword(new Keyword[]{Keyword.manaGain})})), (new ItBill(6, "Honeycomb")).trigger(new AffectSides(SpecificSidesType.RightThree, new AffectSideEffect[]{new AddKeyword(new Keyword[]{Keyword.sixth})})), (new ItBill(6, "Lich Eye")).trigger(new AffectSides(new AffectSideEffect[]{new AddKeyword(new Keyword[]{Keyword.manaGain, Keyword.death}), new FlatBonus(2)})), (new ItBill(6, "Eucalyptus")).trigger(new AffectSides(SpecificSidesType.Right, new AffectSideEffect[]{new ReplaceWith(new EntSide[]{ESB.healCleanse.val(1).withKeyword(Keyword.quadUse)})})), (new ItBill(6, "Tie")).trigger(new AffectSides(SpecificSidesType.Middle, new AffectSideEffect[]{new AddKeyword(new Keyword[]{Keyword.pristine})})), (new ItBill(6, "Karma")).trigger(new AffectSides(new TypeCondition(EffType.Heal, false, false), new AffectSideEffect[]{new AddKeyword(new Keyword[]{Keyword.selfHeal})})).trigger(new AffectSides(new TypeCondition(EffType.Shield, false, false), new AffectSideEffect[]{new AddKeyword(new Keyword[]{Keyword.selfShield})})).trigger(new AffectSides(new TypeCondition(EffType.Damage, false, false), new AffectSideEffect[]{new AddKeyword(new Keyword[]{Keyword.pain})})), (new ItBill(6, "Candle")).trigger(new AffectSides(new AffectSideEffect[]{new AddKeyword(new Keyword[]{Keyword.vigil})})), (new ItBill(6, "Silver Pendant")).trigger(new IncomingEffBonus(2, new EffType[]{EffType.Shield})), (new ItBill(6, "Ghost Shield")).trigger(new StartOfTurnSelf(new Eff[]{(new EffBill()).shield(2).self().bEff()})), (new ItBill(6, "Wrench")).trigger(new AffectSides(SpecificSidesType.Middle, new AffectSideEffect[]{new FlatBonus(1)})), (new ItBill(6, "Blood Amulet")).trigger(new AffectSides(SpecificSidesType.LeftTwo, new AffectSideEffect[]{new AddKeyword(new Keyword[]{Keyword.selfHeal})})), (new ItBill(6, "Catnip")).trigger(new AffectSides(SpecificSidesType.RightMost, new AffectSideEffect[]{new AddKeyword(new Keyword[]{Keyword.cantrip})})), (new ItBill(6, "Tooth Necklace")).trigger(new AffectSides(SpecificSidesType.LeftTwo, new AffectSideEffect[]{new AddKeyword(new Keyword[]{Keyword.cruel})})), (new ItBill(6, "Crescent Shield")).trigger(new AffectSides(SpecificSidesType.Left, new AffectSideEffect[]{new ReplaceWith(new EntSide[]{ESB.shieldCrescent.val(1)})})), (new ItBill(6, "Ocular Amulet")).trigger(new AffectSides(SpecificSidesType.Left, new AffectSideEffect[]{new FlatBonus(1)})), (new ItBill(6, "InfiniHeal")).trigger(new AffectSides(SpecificSidesType.RightTwo, new AffectSideEffect[]{new ChangeType(ESB.healAll, "heal all")})), (new ItBill(6, "Water")).trigger(new AffectSides(SpecificSidesType.Row, new AffectSideEffect[]{new FlatBonus(new int[]{1, -1, 1, -1})})), (new ItBill(6, "Blinding Bolt")).trigger(new AfterUseAbility((Integer)null, (new EffBill()).shield(2).self().bEff())), (new ItBill(6, "Sparks")).trigger(new AffectSides(new ExactlyCondition(1), new AffectSideEffect[]{new AddKeyword(new Keyword[]{Keyword.cantrip})})), (new ItBill(6, "Scales")).trigger(new AffectSides(SpecificSidesType.RightMost, new AffectSideEffect[]{new SetToHighest()})), (new ItBill(6, "Jump")).trigger(new AffectSides(SpecificSidesType.Wings, new AffectSideEffect[]{new AddAllKeywordsFromOtherSides(SpecificSidesType.Left)})).trigger(new AffectSides(SpecificSidesType.Left, new AffectSideEffect[]{new ReplaceWithBlank(ChoosableType.Item)})), new ItBill(6, (new SpellBill()).title("Luck").cost(3).eff((new EffBill()).keywords(new Keyword[]{Keyword.future, Keyword.cooldown}).reroll(8))), (new ItBill(6, "Demonic Deal")).trigger(new AffectSides(new AffectSideEffect[]{new AddKeyword(new Keyword[]{Keyword.pain}), new FlatBonus(2)})), (new ItBill(6, "Twisted Flax")).trigger(new AffectSides(SpecificSidesType.Column, new AffectSideEffect[]{new FlatBonus(new int[]{1, -1, 1})})), (new ItBill(6, "Wand of Stun")).trigger(new AffectSides(SpecificSidesType.Middle, new AffectSideEffect[]{new ReplaceWith(new EntSide[]{ESB.wandStun})})), (new ItBill(6, "Hourglass")).trigger(new PersonalTurnRequirement(new TurnRequirementFirst(), new AffectSides(new AffectSideEffect[]{new FlatBonus(true, new int[]{1})}))), (new ItBill(6, "Cauldron")).trigger(new AffectSides(SpecificSidesType.Middle, new AffectSideEffect[]{new AddKeyword(new Keyword[]{Keyword.rite}), new FlatBonus(1)})), (new ItBill(6, "Conduit")).trigger(new AffectSides(SpecificSidesType.Middle, new AffectSideEffect[]{new ReplaceWith(new EntSide[]{ESB.manaDuplicate.val(2)})})), (new ItBill(6, "Enhance Wand")).trigger(new AffectSides(SpecificSidesType.Top, new AffectSideEffect[]{new ReplaceWith(new EntSide[]{ESB.wandFightBonus.val(1)})})), (new ItBill(7, "Ornate Hilt")).trigger(new AffectSides(new TypeCondition(EffType.Damage), new AffectSideEffect[]{new AddKeyword(new Keyword[]{Keyword.selfShield})})), (new ItBill(7, "Duck")).trigger(new AffectSides(SpecificSidesType.RightTwo, new AffectSideEffect[]{new AddKeyword(new Keyword[]{Keyword.echo})})), (new ItBill(7, "Troll Blood")).trigger(new StartRegenned(2)), (new ItBill(7, "Iron Helm")).trigger(new MaxHP(6)), (new ItBill(7, "Wooden Bracelet")).trigger(new AffectSides(new NoKeywordsCondition(), new AffectSideEffect[]{new FlatBonus(1)})), (new ItBill(7, "Two Reeds")).trigger(new AffectSides(new EvennessCondition(true), new AffectSideEffect[]{new FlatBonus(1)})), (new ItBill(7, "Twisted Bar")).trigger(new AffectSides(new AffectSideEffect[]{new SetValue(2)})), (new ItBill(7, "Thimble")).trigger(new OnMyTurn(new DamageImmunity(true, true, false), "thimble")), (new ItBill(7, "Pair of Kings")).trigger(new AffectSides(SpecificSidesType.Wings, new AffectSideEffect[]{new AddKeyword(new Keyword[]{Keyword.pair})})), (new ItBill(7, "Ichor Chalice")).trigger(new OnOverheal((new EffBill()).damage(1).targetType(TargetingType.Top))), (new ItBill(7, "Second Chance")).trigger(new AffectSides(SpecificSidesType.RightMost, new AffectSideEffect[]{new ReplaceWith(new EntSide[]{ESB.recharge})})), (new ItBill(7, "Sharp Wit")).trigger(new AffectSides(new TypeCondition(EffType.Mana), new AffectSideEffect[]{new ChangeType(ESB.dmg, "basic damage", 3), new RemoveKeyword(new Keyword[]{Keyword.manaGain})})), (new ItBill(7, "Ogre Blood")).trigger(new AffectSides(SpecificSidesType.Middle, new AffectSideEffect[]{new AddKeyword(new Keyword[]{Keyword.bloodlust})})), (new ItBill(7, "Dragon Pipe")).trigger(new AffectSides(new TypeCondition(EffType.Heal), new AffectSideEffect[]{new FlatBonus(1)})), (new ItBill(7, "Metal Studs")).trigger(new AffectSides(new TypeCondition(EffType.Shield), new AffectSideEffect[]{new FlatBonus(1)})), (new ItBill(7, "Demon Claw")).trigger(new AffectSides(SpecificSidesType.Left, new AffectSideEffect[]{new AddKeyword(new Keyword[]{Keyword.rampage}), new FlatBonus(-1)})), (new ItBill(7, "Pocket Mirror")).trigger(new CopySide(SpecificSidesType.Left, SpecificSidesType.RightMost)), (new ItBill(7, "Boots of Speed")).trigger(new TriggerPersonalToGlobal(new GlobalBonusRerolls(1))).trigger(new AffectSides(SpecificSidesType.Left, new AffectSideEffect[]{new ReplaceWith(new EntSide[]{ESB.dodge})})), (new ItBill(7, "Mushroom")).trigger(new AffectSides(new AffectSideEffect[]{new AddKeyword(new Keyword[]{Keyword.decay}), new FlatBonus(1)})), (new ItBill(7, "Flute")).trigger(new AffectSides(SpecificSidesType.RightMost, new AffectSideEffect[]{new ReplaceWith(new EntSide[]{ESB.flute.val(1)})})), (new ItBill(7, "Wandcraft")).trigger(new AffectSides(new AffectSideEffect[]{new ChangeType(ESB.wandMana, "single-use mana")})), (new ItBill(7, "Charge Link")).trigger(new AffectSides(SpecificSidesType.Wings, new AffectSideEffect[]{new AddKeyword(new Keyword[]{Keyword.charged, Keyword.singleUse})})), (new ItBill(7, "Broadsword")).trigger(new AffectSides(SpecificSidesType.Column, new AffectSideEffect[]{new ReplaceWith(new EntSide[]{ESB.dmg.val(4)})})), (new ItBill(7, "Anvil")).trigger(new AffectSides(SpecificSidesType.Middle, new AffectSideEffect[]{new AddKeyword(new Keyword[]{Keyword.steel})})), (new ItBill(7, "Botany")).trigger(new AffectSides(new TypeCondition(EffType.Heal), new AffectSideEffect[]{new AddKeyword(new Keyword[]{Keyword.groupGrowth})})), new ItBill(7, (new SpellBill()).cost(2).title("charge").eff((new EffBill()).shield(2).keywords(new Keyword[]{Keyword.boost, Keyword.singleCast}).friendly())), (new ItBill(7, "Glass Heart")).trigger(new Permadeath()).trigger(new AffectSides(new AffectSideEffect[]{new FlatBonus(1)})), (new ItBill(7, "Burning Halo")).confirmed().trigger(new OnRescue((new EffBill()).group().damage(1).bEff())), (new ItBill(7, "Tentacle")).trigger(new AffectSides(SpecificSidesType.RightTwo, new AffectSideEffect[]{new AddKeyword(new Keyword[]{Keyword.repel})})), (new ItBill(8, "Holy Book")).trigger(new AffectSides(SpecificSidesType.Row, new AffectSideEffect[]{new AddKeyword(new Keyword[]{Keyword.cleanse, Keyword.selfCleanse})})), new ItBill(8, (new SpellBill()).title("Spark").cost(4).eff((new EffBill()).friendly().specialAddKeyword(new Keyword[]{Keyword.manaGain}))), (new ItBill(8, "Poison Dip")).trigger(new AffectSides(SpecificSidesType.Wings, new AffectSideEffect[]{new AddKeyword(new Keyword[]{Keyword.poison})})), (new ItBill(8, "Sickle")).trigger(new AffectSides(new HighestCondition(false), new AffectSideEffect[]{new FlatBonus(1)})), (new ItBill(8, "Tourmaline Paraiba")).trigger(new AffectSides(new TypeCondition(EffType.Mana), new AffectSideEffect[]{new AddKeyword(new Keyword[]{Keyword.era})})), (new ItBill(8, "Tusk")).trigger(new AffectSides(new TypeCondition(EffType.Heal), new AffectSideEffect[]{new FlatBonus(1)})).trigger(new AffectSides(new TypeCondition(EffType.Shield), new AffectSideEffect[]{new FlatBonus(1)})), (new ItBill(8, "Bullseye")).trigger(new AffectSides(SpecificSidesType.Column, new AffectSideEffect[]{new AddKeyword(new Keyword[]{Keyword.engage})})), (new ItBill(8, "Katar")).trigger(new AffectSides(new TypeCondition(EffType.Damage), new AffectSideEffect[]{new AddKeyword(new Keyword[]{Keyword.trio})})), (new ItBill(8, "Prism")).trigger(new AffectSides(SpecificSidesType.Middle, new AffectSideEffect[]{new AddKeyword(new Keyword[]{Keyword.rainbow})})), (new ItBill(8, "Mirror Mask")).trigger(new AffectSides(new AffectSideEffect[]{new CopyBaseFromHeroAbove(true)})), (new ItBill(8, "Scorpion Tail")).trigger(new AffectSides(SpecificSidesType.Wings, new AffectSideEffect[]{new AddKeyword(new Keyword[]{Keyword.weaken, Keyword.pain})})), (new ItBill(8, "Greatsword")).trigger(new AffectSides(SpecificSidesType.Middle, new AffectSideEffect[]{new ReplaceWith(new EntSide[]{ESB.dmgInspire.val(5)})})), (new ItBill(8, "Deadly Bolt")).trigger(new AfterUseAbility((Integer)null, (new EffBill()).damage(1).targetType(TargetingType.Top).bEff())), (new ItBill(8, "Sapphire Ring")).trigger(new AffectSides(new TypeCondition(EffType.Mana), new AffectSideEffect[]{new FlatBonus(1)})), (new ItBill(8, "Faerie Dust")).trigger(new AffectSides(new TypeCondition(EffType.Blank), new AffectSideEffect[]{new ReplaceWith(new EntSide[]{ESB.mana.val(3)})})), (new ItBill(8, "Singularity")).trigger(new AffectSides(SpecificSidesType.RightTwo, new AffectSideEffect[]{new FlatBonus(2)})), (new ItBill(8, "Serration")).trigger(new AffectSides(SpecificSidesType.Wings, new AffectSideEffect[]{new AddKeyword(new Keyword[]{Keyword.vulnerable})})), (new ItBill(8, "Iron Crown")).trigger(new EquipRestrictCol(HeroCol.grey)).trigger(new AffectSides(SpecificSidesType.Left, new AffectSideEffect[]{new FlatBonus(4)})), (new ItBill(8, "Standard")).trigger(new EquipRestrictCol(HeroCol.yellow)).trigger(new AffectSides(new AffectSideEffect[]{new FlatBonus(1)})), (new ItBill(8, "Olympian Trident")).trigger(new AffectSides(SpecificSidesType.Middle, new AffectSideEffect[]{new AddKeyword(new Keyword[]{Keyword.cleave})})), (new ItBill(8, "Sushi")).trigger(new AffectSides(SpecificSidesType.Left, new AffectSideEffect[]{new ReplaceWith(new EntSide[]{ESB.rerollCantrip.val(2)})})), (new ItBill(8, "Brimstone")).trigger(new AffectSides(SpecificSidesType.RightMost, new AffectSideEffect[]{new MultiplyEffect(3)})), (new ItBill(8, "Ironblood Pendant")).trigger(new IncomingEffBonus(3, new EffType[]{EffType.Heal, EffType.Shield})), (new ItBill(8, "Gauntlet")).trigger(new AffectSides(new TypeCondition(EffType.Damage), new AffectSideEffect[]{new FlatBonus(1)})), (new ItBill(8, "Lion")).trigger(new AffectSides(SpecificSidesType.LeftTwo, new AffectSideEffect[]{new AddKeyword(new Keyword[]{Keyword.fierce})})), (new ItBill(8, "Wax Seal")).trigger(new AffectSides(new AffectSideEffect[]{new BonusForIdentical()})), (new ItBill(9, "Boarhide Bracers")).trigger(new AffectSides(SpecificSidesType.Wings, new AffectSideEffect[]{new FlatBonus(2)})), (new ItBill(9, "Timestone")).trigger(new AffectSides(SpecificSidesType.RightTwo, new AffectSideEffect[]{new AddKeyword(new Keyword[]{Keyword.cantrip})})), (new ItBill(9, "Triple Shuriken")).trigger(new AffectSides(new AffectSideEffect[]{new AddKeyword(new Keyword[]{Keyword.ranged, Keyword.chain})})), (new ItBill(9, "Collar")).trigger(new AffectSides(SpecificSidesType.Wings, new AffectSideEffect[]{new AddKeyword(new Keyword[]{Keyword.copycat})})), (new ItBill(9, "Silk Cape")).trigger(new CopySide(SpecificSidesType.Left, SpecificSidesType.Row)), (new ItBill(9, "Emerald Mirror")).trigger(new CopyAlliedItems(6, 8)), (new ItBill(9, "Horned Viper")).trigger(new AffectSides(SpecificSidesType.LeftTwo, new AffectSideEffect[]{new AddKeyword(new Keyword[]{Keyword.poison})})), (new ItBill(9, "Angel Feather")).trigger(new AffectSides(SpecificSidesType.Wings, new AffectSideEffect[]{new AddKeyword(new Keyword[]{Keyword.rescue})})), (new ItBill(9, "Dumbbell")).trigger(new AffectSides(new OrMoreCondition(4), new AffectSideEffect[]{new FlatBonus(4)})), (new ItBill(9, "Chaos Wand")).trigger(new AffectSides(SpecificSidesType.Middle, new AffectSideEffect[]{new ReplaceWith(new EntSide[]{ESB.wandChaos.val(1)})})), (new ItBill(9, "Charged Hammer")).trigger(new AffectSides(SpecificSidesType.Left, new AffectSideEffect[]{new ReplaceWith(new EntSide[]{ESB.chargedHammer.val(10)})})), (new ItBill(9, "Eye of Horus")).trigger(new AffectSides(new AffectSideEffect[]{new FlatBonus(1)})), (new ItBill(9, "Helm of Power")).trigger(new AffectSides(SpecificSidesType.Left, new AffectSideEffect[]{new MultiplyEffect(2)})), (new ItBill(9, "Second Heart")).trigger(new BonusHpPerBase(1, 1)), (new ItBill(9, "Overflowing Chalice")).trigger(SpecificSidesType.RightThree, new AddKeyword(new Keyword[]{Keyword.fizz})), new ItBill(10, (new SpellBill()).title("Abyss").cost(5).eff((new EffBill()).kill().restrict(StateConditionType.HalfOrLessHP).visual(VisualEffectType.Singularity))), (new ItBill(9, "Spike Stone")).trigger(new AffectSides(SpecificSidesType.Column, new AffectSideEffect[]{new AddKeyword(new Keyword[]{Keyword.fumble}), new FlatBonus(3)}))); } }
